2019-11-02 15:58:29,261 ERROR: Exception on /reset_password_request [POST] [in /home/ubuntu/.local/lib/python3.7/site-packages/flask/app.py:1891]
Traceback (most recent call last):
  File "/home/ubuntu/.local/lib/python3.7/site-packages/flask/app.py", line 2446, in wsgi_app
    response = self.full_dispatch_request()
  File "/home/ubuntu/.local/lib/python3.7/site-packages/flask/app.py", line 1951, in full_dispatch_request
    rv = self.handle_user_exception(e)
  File "/home/ubuntu/.local/lib/python3.7/site-packages/flask/app.py", line 1820, in handle_user_exception
    reraise(exc_type, exc_value, tb)
  File "/home/ubuntu/.local/lib/python3.7/site-packages/flask/_compat.py", line 39, in reraise
    raise value
  File "/home/ubuntu/.local/lib/python3.7/site-packages/flask/app.py", line 1949, in full_dispatch_request
    rv = self.dispatch_request()
  File "/home/ubuntu/.local/lib/python3.7/site-packages/flask/app.py", line 1935, in dispatch_request
    return self.view_functions[rule.endpoint](**req.view_args)
  File "/home/ubuntu/nea_project/app/routes.py", line 136, in reset_password_request
    send_password_reset_email(user)
  File "/home/ubuntu/nea_project/app/email.py", line 19, in send_password_reset_email
    user=user, token=token))
  File "/home/ubuntu/nea_project/app/email.py", line 9, in send_email
    mail.send(msg)
  File "/home/ubuntu/.local/lib/python3.7/site-packages/flask_mail.py", line 491, in send
    with self.connect() as connection:
  File "/home/ubuntu/.local/lib/python3.7/site-packages/flask_mail.py", line 144, in __enter__
    self.host = self.configure_host()
  File "/home/ubuntu/.local/lib/python3.7/site-packages/flask_mail.py", line 158, in configure_host
    host = smtplib.SMTP(self.mail.server, self.mail.port)
  File "/usr/local/lib/python3.7/smtplib.py", line 251, in __init__
    (code, msg) = self.connect(host, port)
  File "/usr/local/lib/python3.7/smtplib.py", line 336, in connect
    self.sock = self._get_socket(host, port, self.timeout)
  File "/usr/local/lib/python3.7/smtplib.py", line 307, in _get_socket
    self.source_address)
  File "/usr/local/lib/python3.7/socket.py", line 727, in create_connection
    raise err
  File "/usr/local/lib/python3.7/socket.py", line 716, in create_connection
    sock.connect(sa)
OSError: [Errno 99] Cannot assign requested address
2019-11-02 15:58:42,665 INFO: WYJP startup [in /home/ubuntu/nea_project/app/__init__.py:47]
2019-11-02 16:01:21,384 INFO: WYJP startup [in /home/ubuntu/nea_project/app/__init__.py:47]
2019-11-02 19:55:54,185 INFO: WYJP startup [in /home/ubuntu/nea_project/app/__init__.py:47]
2019-11-03 12:52:26,114 INFO: WYJP startup [in /home/ubuntu/nea_project/app/__init__.py:47]
2019-11-03 12:53:16,467 INFO: WYJP startup [in /home/ubuntu/nea_project/app/__init__.py:47]
2019-11-03 12:56:14,786 INFO: WYJP startup [in /home/ubuntu/nea_project/app/__init__.py:47]
2019-11-03 13:27:37,585 INFO: WYJP startup [in /home/ubuntu/nea_project/app/__init__.py:47]
2019-11-03 13:29:47,303 INFO: WYJP startup [in /home/ubuntu/nea_project/app/__init__.py:47]
2019-11-03 16:40:45,205 INFO: WYJP startup [in /home/ubuntu/nea_project/app/__init__.py:47]
2019-11-03 16:42:56,197 INFO: WYJP startup [in /home/ubuntu/nea_project/app/__init__.py:47]
2019-11-03 16:47:38,583 INFO: WYJP startup [in /home/ubuntu/nea_project/app/__init__.py:47]
2019-11-03 16:48:44,905 INFO: WYJP startup [in /home/ubuntu/nea_project/app/__init__.py:47]
2019-11-03 16:50:13,809 INFO: WYJP startup [in /home/ubuntu/nea_project/app/__init__.py:47]
2019-11-04 16:49:37,972 INFO: WYJP startup [in /home/ubuntu/nea_project/app/__init__.py:52]
2019-11-04 16:49:47,193 ERROR: Exception on /auth/logout [GET] [in /home/ubuntu/.local/lib/python3.7/site-packages/flask/app.py:1891]
Traceback (most recent call last):
  File "/home/ubuntu/.local/lib/python3.7/site-packages/flask/app.py", line 2446, in wsgi_app
    response = self.full_dispatch_request()
  File "/home/ubuntu/.local/lib/python3.7/site-packages/flask/app.py", line 1951, in full_dispatch_request
    rv = self.handle_user_exception(e)
  File "/home/ubuntu/.local/lib/python3.7/site-packages/flask/app.py", line 1820, in handle_user_exception
    reraise(exc_type, exc_value, tb)
  File "/home/ubuntu/.local/lib/python3.7/site-packages/flask/_compat.py", line 39, in reraise
    raise value
  File "/home/ubuntu/.local/lib/python3.7/site-packages/flask/app.py", line 1949, in full_dispatch_request
    rv = self.dispatch_request()
  File "/home/ubuntu/.local/lib/python3.7/site-packages/flask/app.py", line 1935, in dispatch_request
    return self.view_functions[rule.endpoint](**req.view_args)
  File "/home/ubuntu/nea_project/app/auth/routes.py", line 33, in logout
    return redirect(url_for('login'))
  File "/home/ubuntu/.local/lib/python3.7/site-packages/flask/helpers.py", line 370, in url_for
    return appctx.app.handle_url_build_error(error, endpoint, values)
  File "/home/ubuntu/.local/lib/python3.7/site-packages/flask/app.py", line 2215, in handle_url_build_error
    reraise(exc_type, exc_value, tb)
  File "/home/ubuntu/.local/lib/python3.7/site-packages/flask/_compat.py", line 39, in reraise
    raise value
  File "/home/ubuntu/.local/lib/python3.7/site-packages/flask/helpers.py", line 358, in url_for
    endpoint, values, method=method, force_external=external
  File "/home/ubuntu/.local/lib/python3.7/site-packages/werkzeug/routing.py", line 2020, in build
    raise BuildError(endpoint, values, method, self)
werkzeug.routing.BuildError: Could not build url for endpoint 'login'. Did you mean 'auth.login' instead?
2019-11-04 16:51:01,186 INFO: WYJP startup [in /home/ubuntu/nea_project/app/__init__.py:52]
2019-11-04 16:51:11,182 ERROR: Exception on /auth/login [GET] [in /home/ubuntu/.local/lib/python3.7/site-packages/flask/app.py:1891]
Traceback (most recent call last):
  File "/home/ubuntu/.local/lib/python3.7/site-packages/flask/app.py", line 2446, in wsgi_app
    response = self.full_dispatch_request()
  File "/home/ubuntu/.local/lib/python3.7/site-packages/flask/app.py", line 1951, in full_dispatch_request
    rv = self.handle_user_exception(e)
  File "/home/ubuntu/.local/lib/python3.7/site-packages/flask/app.py", line 1820, in handle_user_exception
    reraise(exc_type, exc_value, tb)
  File "/home/ubuntu/.local/lib/python3.7/site-packages/flask/_compat.py", line 39, in reraise
    raise value
  File "/home/ubuntu/.local/lib/python3.7/site-packages/flask/app.py", line 1949, in full_dispatch_request
    rv = self.dispatch_request()
  File "/home/ubuntu/.local/lib/python3.7/site-packages/flask/app.py", line 1935, in dispatch_request
    return self.view_functions[rule.endpoint](**req.view_args)
  File "/home/ubuntu/nea_project/app/auth/routes.py", line 28, in login
    return render_template('auth/login.html', title='Login', form=form)
  File "/home/ubuntu/.local/lib/python3.7/site-packages/flask/templating.py", line 140, in render_template
    ctx.app,
  File "/home/ubuntu/.local/lib/python3.7/site-packages/flask/templating.py", line 120, in _render
    rv = template.render(context)
  File "/home/ubuntu/.local/lib/python3.7/site-packages/jinja2/asyncsupport.py", line 76, in render
    return original_render(self, *args, **kwargs)
  File "/home/ubuntu/.local/lib/python3.7/site-packages/jinja2/environment.py", line 1008, in render
    return self.environment.handle_exception(exc_info, True)
  File "/home/ubuntu/.local/lib/python3.7/site-packages/jinja2/environment.py", line 780, in handle_exception
    reraise(exc_type, exc_value, tb)
  File "/home/ubuntu/.local/lib/python3.7/site-packages/jinja2/_compat.py", line 37, in reraise
    raise value.with_traceback(tb)
  File "/home/ubuntu/nea_project/app/templates/auth/login.html", line 2, in top-level template code
    {% import "bootstrap/wtf.html" as wtf %}
  File "/home/ubuntu/.local/lib/python3.7/site-packages/jinja2/environment.py", line 1005, in render
    return concat(self.root_render_func(self.new_context(vars)))
  File "/home/ubuntu/nea_project/app/templates/auth/login.html", line 17, in root
    </center>
  File "/home/ubuntu/nea_project/app/templates/base.html", line 14, in root
    <!-- Custom CSS, JS & Favicon (Including FontAwesome) -->
  File "/home/ubuntu/.local/lib/python3.7/site-packages/flask_bootstrap/templates/bootstrap/base.html", line 10, in root
    <meta name="viewport" content="width=device-width, initial-scale=1.0">
  File "/home/ubuntu/.local/lib/python3.7/site-packages/flask_bootstrap/templates/bootstrap/base.html", line 20, in block_doc
    {% block body -%}
  File "/home/ubuntu/.local/lib/python3.7/site-packages/flask_bootstrap/templates/bootstrap/base.html", line 39, in block_html
  File "/home/ubuntu/.local/lib/python3.7/site-packages/flask_bootstrap/templates/bootstrap/base.html", line 92, in block_body
  File "/home/ubuntu/nea_project/app/templates/auth/login.html", line 30, in block_content
  File "/home/ubuntu/.local/lib/python3.7/site-packages/jinja2/runtime.py", line 262, in call
    return __obj(*args, **kwargs)
  File "/home/ubuntu/.local/lib/python3.7/site-packages/flask/helpers.py", line 370, in url_for
    return appctx.app.handle_url_build_error(error, endpoint, values)
  File "/home/ubuntu/.local/lib/python3.7/site-packages/flask/app.py", line 2215, in handle_url_build_error
    reraise(exc_type, exc_value, tb)
  File "/home/ubuntu/.local/lib/python3.7/site-packages/flask/_compat.py", line 39, in reraise
    raise value
  File "/home/ubuntu/.local/lib/python3.7/site-packages/flask/helpers.py", line 358, in url_for
    endpoint, values, method=method, force_external=external
  File "/home/ubuntu/.local/lib/python3.7/site-packages/werkzeug/routing.py", line 2020, in build
    raise BuildError(endpoint, values, method, self)
werkzeug.routing.BuildError: Could not build url for endpoint 'register'. Did you mean 'auth.register' instead?
2019-11-04 16:52:29,004 INFO: WYJP startup [in /home/ubuntu/nea_project/app/__init__.py:52]
2019-11-04 20:19:48,665 INFO: WYJP startup [in /home/ubuntu/nea_project/app/__init__.py:59]
2019-11-04 20:20:40,274 INFO: WYJP startup [in /home/ubuntu/nea_project/app/__init__.py:59]
